2013-09-26 13:22:42,640 [Thread-3:1360] [django.request:212] [ERROR]- Internal Server Error: /account/signin/
Traceback (most recent call last):
  File "C:\Python27\lib\site-packages\django\core\handlers\base.py", line 115, in get_response
    response = callback(request, *callback_args, **callback_kwargs)
  File "F:\PythonWork\c28\account\views.py", line 14, in signin
    value = form.cleaned_data
AttributeError: 'SigninForm' object has no attribute 'cleaned_data'
2013-09-26 13:23:32,171 [Thread-1:3236] [django.request:212] [ERROR]- Internal Server Error: /account/signin/
Traceback (most recent call last):
  File "C:\Python27\lib\site-packages\django\core\handlers\base.py", line 115, in get_response
    response = callback(request, *callback_args, **callback_kwargs)
  File "F:\PythonWork\c28\account\views.py", line 14, in signin
    value = form.clean()
  File "F:\PythonWork\c28\account\form.py", line 23, in clean
    if "password" in self.cleaned_data and "password_confirm" in self.cleaned_data:
AttributeError: 'SigninForm' object has no attribute 'cleaned_data'
2013-09-26 13:23:42,155 [Thread-5:4644] [django.request:212] [ERROR]- Internal Server Error: /account/signin/
Traceback (most recent call last):
  File "C:\Python27\lib\site-packages\django\core\handlers\base.py", line 115, in get_response
    response = callback(request, *callback_args, **callback_kwargs)
  File "F:\PythonWork\c28\account\views.py", line 14, in signin
    value = form.clean()
  File "F:\PythonWork\c28\account\form.py", line 23, in clean
    if "password" in self.cleaned_data and "password_confirm" in self.cleaned_data:
AttributeError: 'SigninForm' object has no attribute 'cleaned_data'
2013-09-26 14:39:07,092 [Thread-10:6104] [django.request:194] [WARNING]- Forbidden (CSRF token missing or incorrect.): /account/signin/
2013-09-26 14:51:12,092 [Thread-4:5996] [django.request:146] [WARNING]- Not Found: /account/signin/account/signin.html
2013-09-26 14:51:30,858 [Thread-4:5036] [django.request:146] [WARNING]- Not Found: /account/signin/signin.html
2013-09-26 14:52:11,155 [Thread-4:4212] [django.request:146] [WARNING]- Not Found: /account/signin/account/signin.html
2013-09-26 14:52:51,375 [Thread-4:4376] [django.request:194] [WARNING]- Forbidden (CSRF token missing or incorrect.): /account/signin/
2013-09-26 14:54:34,608 [Thread-5:2440] [django.request:212] [ERROR]- Internal Server Error: /account/
Traceback (most recent call last):
  File "C:\Python27\lib\site-packages\django\core\handlers\base.py", line 115, in get_response
    response = callback(request, *callback_args, **callback_kwargs)
  File "F:\PythonWork\c28\account\views.py", line 11, in signup
    return render_to_response('account/signin.html',context_instance=RequestContext(request))
  File "C:\Python27\lib\site-packages\django\shortcuts\__init__.py", line 29, in render_to_response
    return HttpResponse(loader.render_to_string(*args, **kwargs), **httpresponse_kwargs)
  File "C:\Python27\lib\site-packages\django\template\loader.py", line 170, in render_to_string
    t = get_template(template_name)
  File "C:\Python27\lib\site-packages\django\template\loader.py", line 146, in get_template
    template, origin = find_template(template_name)
  File "C:\Python27\lib\site-packages\django\template\loader.py", line 135, in find_template
    source, display_name = loader(name, dirs)
  File "C:\Python27\lib\site-packages\django\template\loader.py", line 43, in __call__
    return self.load_template(template_name, template_dirs)
  File "C:\Python27\lib\site-packages\django\template\loader.py", line 49, in load_template
    template = get_template_from_string(source, origin, template_name)
  File "C:\Python27\lib\site-packages\django\template\loader.py", line 157, in get_template_from_string
    return Template(source, origin, name)
  File "C:\Python27\lib\site-packages\django\template\base.py", line 125, in __init__
    self.nodelist = compile_string(template_string, origin)
  File "C:\Python27\lib\site-packages\django\template\base.py", line 153, in compile_string
    return parser.parse()
  File "C:\Python27\lib\site-packages\django\template\base.py", line 253, in parse
    filter_expression = self.compile_filter(token.contents)
  File "C:\Python27\lib\site-packages\django\template\base.py", line 353, in compile_filter
    return FilterExpression(token, self)
  File "C:\Python27\lib\site-packages\django\template\base.py", line 570, in __init__
    "from '%s'" % (token[upto:], token))
TemplateSyntaxError: Could not parse the remainder: '% if form.errors %' from '% if form.errors %'
2013-09-26 14:55:03,265 [Thread-6:4404] [django.request:212] [ERROR]- Internal Server Error: /account/
Traceback (most recent call last):
  File "C:\Python27\lib\site-packages\django\core\handlers\base.py", line 115, in get_response
    response = callback(request, *callback_args, **callback_kwargs)
  File "F:\PythonWork\c28\account\views.py", line 11, in signup
    return render_to_response('account/signin.html',context_instance=RequestContext(request))
  File "C:\Python27\lib\site-packages\django\shortcuts\__init__.py", line 29, in render_to_response
    return HttpResponse(loader.render_to_string(*args, **kwargs), **httpresponse_kwargs)
  File "C:\Python27\lib\site-packages\django\template\loader.py", line 170, in render_to_string
    t = get_template(template_name)
  File "C:\Python27\lib\site-packages\django\template\loader.py", line 146, in get_template
    template, origin = find_template(template_name)
  File "C:\Python27\lib\site-packages\django\template\loader.py", line 135, in find_template
    source, display_name = loader(name, dirs)
  File "C:\Python27\lib\site-packages\django\template\loader.py", line 43, in __call__
    return self.load_template(template_name, template_dirs)
  File "C:\Python27\lib\site-packages\django\template\loader.py", line 49, in load_template
    template = get_template_from_string(source, origin, template_name)
  File "C:\Python27\lib\site-packages\django\template\loader.py", line 157, in get_template_from_string
    return Template(source, origin, name)
  File "C:\Python27\lib\site-packages\django\template\base.py", line 125, in __init__
    self.nodelist = compile_string(template_string, origin)
  File "C:\Python27\lib\site-packages\django\template\base.py", line 153, in compile_string
    return parser.parse()
  File "C:\Python27\lib\site-packages\django\template\base.py", line 253, in parse
    filter_expression = self.compile_filter(token.contents)
  File "C:\Python27\lib\site-packages\django\template\base.py", line 353, in compile_filter
    return FilterExpression(token, self)
  File "C:\Python27\lib\site-packages\django\template\base.py", line 570, in __init__
    "from '%s'" % (token[upto:], token))
TemplateSyntaxError: Could not parse the remainder: '% if form.errors %' from '% if form.errors %'
2013-09-26 14:58:01,500 [Thread-9:1872] [django.request:194] [WARNING]- Forbidden (CSRF token missing or incorrect.): /account/signin/
2013-09-26 15:01:57,905 [Thread-4:2472] [django.request:146] [WARNING]- Not Found: /account/signin.html
2013-09-26 15:02:41,733 [Thread-3:5228] [django.request:194] [WARNING]- Forbidden (CSRF token missing or incorrect.): /account/signin/
2013-09-26 15:06:10,265 [Thread-4:500] [django.request:194] [WARNING]- Forbidden (CSRF token missing or incorrect.): /account/signin/
2013-09-26 15:44:17,250 [Thread-15:1924] [django.request:194] [WARNING]- Forbidden (CSRF token missing or incorrect.): /account/signin/
2013-09-26 15:52:08,812 [Thread-23:572] [django.request:146] [WARNING]- Not Found: /account/welcome.html
2013-10-02 14:04:30,543 [Thread-1:-1244660928] [django.request:212] [ERROR]- Internal Server Error: /
Traceback (most recent call last):
  File "/usr/local/lib/python2.7/dist-packages/django/core/handlers/base.py", line 103, in get_response
    resolver_match = resolver.resolve(request.path_info)
  File "/usr/local/lib/python2.7/dist-packages/django/core/urlresolvers.py", line 319, in resolve
    for pattern in self.url_patterns:
  File "/usr/local/lib/python2.7/dist-packages/django/core/urlresolvers.py", line 347, in url_patterns
    patterns = getattr(self.urlconf_module, "urlpatterns", self.urlconf_module)
  File "/usr/local/lib/python2.7/dist-packages/django/core/urlresolvers.py", line 342, in urlconf_module
    self._urlconf_module = import_module(self.urlconf_name)
  File "/usr/local/lib/python2.7/dist-packages/django/utils/importlib.py", line 35, in import_module
    __import__(name)
  File "/home/cc/djcode/c28/c28/urls.py", line 16, in <module>
    url(r'forum/', forum),
NameError: name 'forum' is not defined
2013-10-02 14:04:30,840 [Thread-3:-1244660928] [django.request:212] [ERROR]- Internal Server Error: /favicon.ico
Traceback (most recent call last):
  File "/usr/local/lib/python2.7/dist-packages/django/core/handlers/base.py", line 92, in get_response
    response = middleware_method(request)
  File "/usr/local/lib/python2.7/dist-packages/django/middleware/common.py", line 69, in process_request
    if (not urlresolvers.is_valid_path(request.path_info, urlconf) and
  File "/usr/local/lib/python2.7/dist-packages/django/core/urlresolvers.py", line 551, in is_valid_path
    resolve(path, urlconf)
  File "/usr/local/lib/python2.7/dist-packages/django/core/urlresolvers.py", line 440, in resolve
    return get_resolver(urlconf).resolve(path)
  File "/usr/local/lib/python2.7/dist-packages/django/core/urlresolvers.py", line 319, in resolve
    for pattern in self.url_patterns:
  File "/usr/local/lib/python2.7/dist-packages/django/core/urlresolvers.py", line 347, in url_patterns
    patterns = getattr(self.urlconf_module, "urlpatterns", self.urlconf_module)
  File "/usr/local/lib/python2.7/dist-packages/django/core/urlresolvers.py", line 342, in urlconf_module
    self._urlconf_module = import_module(self.urlconf_name)
  File "/usr/local/lib/python2.7/dist-packages/django/utils/importlib.py", line 35, in import_module
    __import__(name)
  File "/home/cc/djcode/c28/c28/urls.py", line 16, in <module>
    url(r'forum/', forum),
NameError: name 'forum' is not defined
2013-10-02 14:04:30,924 [Thread-4:-1244660928] [django.request:212] [ERROR]- Internal Server Error: /favicon.ico
Traceback (most recent call last):
  File "/usr/local/lib/python2.7/dist-packages/django/core/handlers/base.py", line 92, in get_response
    response = middleware_method(request)
  File "/usr/local/lib/python2.7/dist-packages/django/middleware/common.py", line 69, in process_request
    if (not urlresolvers.is_valid_path(request.path_info, urlconf) and
  File "/usr/local/lib/python2.7/dist-packages/django/core/urlresolvers.py", line 551, in is_valid_path
    resolve(path, urlconf)
  File "/usr/local/lib/python2.7/dist-packages/django/core/urlresolvers.py", line 440, in resolve
    return get_resolver(urlconf).resolve(path)
  File "/usr/local/lib/python2.7/dist-packages/django/core/urlresolvers.py", line 319, in resolve
    for pattern in self.url_patterns:
  File "/usr/local/lib/python2.7/dist-packages/django/core/urlresolvers.py", line 347, in url_patterns
    patterns = getattr(self.urlconf_module, "urlpatterns", self.urlconf_module)
  File "/usr/local/lib/python2.7/dist-packages/django/core/urlresolvers.py", line 342, in urlconf_module
    self._urlconf_module = import_module(self.urlconf_name)
  File "/usr/local/lib/python2.7/dist-packages/django/utils/importlib.py", line 35, in import_module
    __import__(name)
  File "/home/cc/djcode/c28/c28/urls.py", line 16, in <module>
    url(r'forum/', forum),
NameError: name 'forum' is not defined
2013-10-02 14:06:23,469 [Thread-1:-1244660928] [django.request:212] [ERROR]- Internal Server Error: /
Traceback (most recent call last):
  File "/usr/local/lib/python2.7/dist-packages/django/core/handlers/base.py", line 103, in get_response
    resolver_match = resolver.resolve(request.path_info)
  File "/usr/local/lib/python2.7/dist-packages/django/core/urlresolvers.py", line 319, in resolve
    for pattern in self.url_patterns:
  File "/usr/local/lib/python2.7/dist-packages/django/core/urlresolvers.py", line 347, in url_patterns
    patterns = getattr(self.urlconf_module, "urlpatterns", self.urlconf_module)
  File "/usr/local/lib/python2.7/dist-packages/django/core/urlresolvers.py", line 342, in urlconf_module
    self._urlconf_module = import_module(self.urlconf_name)
  File "/usr/local/lib/python2.7/dist-packages/django/utils/importlib.py", line 35, in import_module
    __import__(name)
  File "/home/cc/djcode/c28/c28/urls.py", line 16, in <module>
    url(r'forum/', forum),
NameError: name 'forum' is not defined
2013-10-02 14:07:48,564 [Thread-3:-1244660928] [django.request:212] [ERROR]- Internal Server Error: /
Traceback (most recent call last):
  File "/usr/local/lib/python2.7/dist-packages/django/core/handlers/base.py", line 103, in get_response
    resolver_match = resolver.resolve(request.path_info)
  File "/usr/local/lib/python2.7/dist-packages/django/core/urlresolvers.py", line 319, in resolve
    for pattern in self.url_patterns:
  File "/usr/local/lib/python2.7/dist-packages/django/core/urlresolvers.py", line 347, in url_patterns
    patterns = getattr(self.urlconf_module, "urlpatterns", self.urlconf_module)
  File "/usr/local/lib/python2.7/dist-packages/django/core/urlresolvers.py", line 342, in urlconf_module
    self._urlconf_module = import_module(self.urlconf_name)
  File "/usr/local/lib/python2.7/dist-packages/django/utils/importlib.py", line 35, in import_module
    __import__(name)
  File "/home/cc/djcode/c28/c28/urls.py", line 17, in <module>
    url(r'forum/', forum),
NameError: name 'forum' is not defined
2013-10-02 14:07:50,635 [Thread-4:-1244660928] [django.request:212] [ERROR]- Internal Server Error: /
Traceback (most recent call last):
  File "/usr/local/lib/python2.7/dist-packages/django/core/handlers/base.py", line 103, in get_response
    resolver_match = resolver.resolve(request.path_info)
  File "/usr/local/lib/python2.7/dist-packages/django/core/urlresolvers.py", line 319, in resolve
    for pattern in self.url_patterns:
  File "/usr/local/lib/python2.7/dist-packages/django/core/urlresolvers.py", line 347, in url_patterns
    patterns = getattr(self.urlconf_module, "urlpatterns", self.urlconf_module)
  File "/usr/local/lib/python2.7/dist-packages/django/core/urlresolvers.py", line 342, in urlconf_module
    self._urlconf_module = import_module(self.urlconf_name)
  File "/usr/local/lib/python2.7/dist-packages/django/utils/importlib.py", line 35, in import_module
    __import__(name)
  File "/home/cc/djcode/c28/c28/urls.py", line 17, in <module>
    url(r'forum/', forum),
NameError: name 'forum' is not defined
2013-10-02 14:09:09,291 [Thread-6:-1244660928] [django.request:212] [ERROR]- Internal Server Error: /forum
Traceback (most recent call last):
  File "/usr/local/lib/python2.7/dist-packages/django/core/handlers/base.py", line 92, in get_response
    response = middleware_method(request)
  File "/usr/local/lib/python2.7/dist-packages/django/middleware/common.py", line 70, in process_request
    urlresolvers.is_valid_path("%s/" % request.path_info, urlconf)):
  File "/usr/local/lib/python2.7/dist-packages/django/core/urlresolvers.py", line 551, in is_valid_path
    resolve(path, urlconf)
  File "/usr/local/lib/python2.7/dist-packages/django/core/urlresolvers.py", line 440, in resolve
    return get_resolver(urlconf).resolve(path)
  File "/usr/local/lib/python2.7/dist-packages/django/core/urlresolvers.py", line 321, in resolve
    sub_match = pattern.resolve(new_path)
  File "/usr/local/lib/python2.7/dist-packages/django/core/urlresolvers.py", line 223, in resolve
    return ResolverMatch(self.callback, args, kwargs, self.name)
  File "/usr/local/lib/python2.7/dist-packages/django/core/urlresolvers.py", line 230, in callback
    self._callback = get_callable(self._callback_str)
  File "/usr/local/lib/python2.7/dist-packages/django/utils/functional.py", line 31, in wrapper
    result = func(*args)
  File "/usr/local/lib/python2.7/dist-packages/django/core/urlresolvers.py", line 97, in get_callable
    mod = import_module(mod_name)
  File "/usr/local/lib/python2.7/dist-packages/django/utils/importlib.py", line 35, in import_module
    __import__(name)
  File "/home/cc/djcode/c28/topics/views.py", line 5
    def forum(request)
                     ^
SyntaxError: invalid syntax
2013-10-02 14:09:57,926 [Thread-8:-1244660928] [django.request:212] [ERROR]- Internal Server Error: /forum/
Traceback (most recent call last):
  File "/usr/local/lib/python2.7/dist-packages/django/core/handlers/base.py", line 115, in get_response
    response = callback(request, *callback_args, **callback_kwargs)
  File "/home/cc/djcode/c28/topics/views.py", line 6, in forum
    return render_to_response('forum.html')
  File "/usr/local/lib/python2.7/dist-packages/django/shortcuts/__init__.py", line 29, in render_to_response
    return HttpResponse(loader.render_to_string(*args, **kwargs), **httpresponse_kwargs)
  File "/usr/local/lib/python2.7/dist-packages/django/template/loader.py", line 170, in render_to_string
    t = get_template(template_name)
  File "/usr/local/lib/python2.7/dist-packages/django/template/loader.py", line 146, in get_template
    template, origin = find_template(template_name)
  File "/usr/local/lib/python2.7/dist-packages/django/template/loader.py", line 139, in find_template
    raise TemplateDoesNotExist(name)
TemplateDoesNotExist: forum.html
2013-10-02 14:12:52,522 [Thread-3:-1244660928] [django.request:146] [WARNING]- Not Found: /topic/new
2013-10-02 14:19:03,735 [Thread-1:-1246758080] [django.request:212] [ERROR]- Internal Server Error: /topic/new
Traceback (most recent call last):
  File "/usr/local/lib/python2.7/dist-packages/django/core/handlers/base.py", line 92, in get_response
    response = middleware_method(request)
  File "/usr/local/lib/python2.7/dist-packages/django/middleware/common.py", line 69, in process_request
    if (not urlresolvers.is_valid_path(request.path_info, urlconf) and
  File "/usr/local/lib/python2.7/dist-packages/django/core/urlresolvers.py", line 551, in is_valid_path
    resolve(path, urlconf)
  File "/usr/local/lib/python2.7/dist-packages/django/core/urlresolvers.py", line 440, in resolve
    return get_resolver(urlconf).resolve(path)
  File "/usr/local/lib/python2.7/dist-packages/django/core/urlresolvers.py", line 321, in resolve
    sub_match = pattern.resolve(new_path)
  File "/usr/local/lib/python2.7/dist-packages/django/core/urlresolvers.py", line 223, in resolve
    return ResolverMatch(self.callback, args, kwargs, self.name)
  File "/usr/local/lib/python2.7/dist-packages/django/core/urlresolvers.py", line 230, in callback
    self._callback = get_callable(self._callback_str)
  File "/usr/local/lib/python2.7/dist-packages/django/utils/functional.py", line 31, in wrapper
    result = func(*args)
  File "/usr/local/lib/python2.7/dist-packages/django/core/urlresolvers.py", line 118, in get_callable
    (lookup_view, mod_name))
ViewDoesNotExist: Could not import topics.views.topic_new. View does not exist in module topics.views.
2013-10-02 14:19:25,174 [Thread-3:-1243612352] [django.request:212] [ERROR]- Internal Server Error: /topic/new
Traceback (most recent call last):
  File "/usr/local/lib/python2.7/dist-packages/django/core/handlers/base.py", line 92, in get_response
    response = middleware_method(request)
  File "/usr/local/lib/python2.7/dist-packages/django/middleware/common.py", line 70, in process_request
    urlresolvers.is_valid_path("%s/" % request.path_info, urlconf)):
  File "/usr/local/lib/python2.7/dist-packages/django/core/urlresolvers.py", line 551, in is_valid_path
    resolve(path, urlconf)
  File "/usr/local/lib/python2.7/dist-packages/django/core/urlresolvers.py", line 440, in resolve
    return get_resolver(urlconf).resolve(path)
  File "/usr/local/lib/python2.7/dist-packages/django/core/urlresolvers.py", line 321, in resolve
    sub_match = pattern.resolve(new_path)
  File "/usr/local/lib/python2.7/dist-packages/django/core/urlresolvers.py", line 223, in resolve
    return ResolverMatch(self.callback, args, kwargs, self.name)
  File "/usr/local/lib/python2.7/dist-packages/django/core/urlresolvers.py", line 230, in callback
    self._callback = get_callable(self._callback_str)
  File "/usr/local/lib/python2.7/dist-packages/django/utils/functional.py", line 31, in wrapper
    result = func(*args)
  File "/usr/local/lib/python2.7/dist-packages/django/core/urlresolvers.py", line 118, in get_callable
    (lookup_view, mod_name))
ViewDoesNotExist: Could not import topics.views.topic_new. View does not exist in module topics.views.
2013-10-02 14:20:52,805 [Thread-1:-1243612352] [django.request:212] [ERROR]- Internal Server Error: /topic/new
Traceback (most recent call last):
  File "/usr/local/lib/python2.7/dist-packages/django/core/handlers/base.py", line 92, in get_response
    response = middleware_method(request)
  File "/usr/local/lib/python2.7/dist-packages/django/middleware/common.py", line 70, in process_request
    urlresolvers.is_valid_path("%s/" % request.path_info, urlconf)):
  File "/usr/local/lib/python2.7/dist-packages/django/core/urlresolvers.py", line 551, in is_valid_path
    resolve(path, urlconf)
  File "/usr/local/lib/python2.7/dist-packages/django/core/urlresolvers.py", line 440, in resolve
    return get_resolver(urlconf).resolve(path)
  File "/usr/local/lib/python2.7/dist-packages/django/core/urlresolvers.py", line 321, in resolve
    sub_match = pattern.resolve(new_path)
  File "/usr/local/lib/python2.7/dist-packages/django/core/urlresolvers.py", line 223, in resolve
    return ResolverMatch(self.callback, args, kwargs, self.name)
  File "/usr/local/lib/python2.7/dist-packages/django/core/urlresolvers.py", line 230, in callback
    self._callback = get_callable(self._callback_str)
  File "/usr/local/lib/python2.7/dist-packages/django/utils/functional.py", line 31, in wrapper
    result = func(*args)
  File "/usr/local/lib/python2.7/dist-packages/django/core/urlresolvers.py", line 118, in get_callable
    (lookup_view, mod_name))
ViewDoesNotExist: Could not import topics.views.topic_new. View does not exist in module topics.views.
2013-10-02 14:20:54,131 [Thread-3:-1243612352] [django.request:212] [ERROR]- Internal Server Error: /topic/new
Traceback (most recent call last):
  File "/usr/local/lib/python2.7/dist-packages/django/core/handlers/base.py", line 92, in get_response
    response = middleware_method(request)
  File "/usr/local/lib/python2.7/dist-packages/django/middleware/common.py", line 70, in process_request
    urlresolvers.is_valid_path("%s/" % request.path_info, urlconf)):
  File "/usr/local/lib/python2.7/dist-packages/django/core/urlresolvers.py", line 551, in is_valid_path
    resolve(path, urlconf)
  File "/usr/local/lib/python2.7/dist-packages/django/core/urlresolvers.py", line 440, in resolve
    return get_resolver(urlconf).resolve(path)
  File "/usr/local/lib/python2.7/dist-packages/django/core/urlresolvers.py", line 321, in resolve
    sub_match = pattern.resolve(new_path)
  File "/usr/local/lib/python2.7/dist-packages/django/core/urlresolvers.py", line 223, in resolve
    return ResolverMatch(self.callback, args, kwargs, self.name)
  File "/usr/local/lib/python2.7/dist-packages/django/core/urlresolvers.py", line 230, in callback
    self._callback = get_callable(self._callback_str)
  File "/usr/local/lib/python2.7/dist-packages/django/utils/functional.py", line 31, in wrapper
    result = func(*args)
  File "/usr/local/lib/python2.7/dist-packages/django/core/urlresolvers.py", line 118, in get_callable
    (lookup_view, mod_name))
ViewDoesNotExist: Could not import topics.views.topic_new. View does not exist in module topics.views.
2013-10-02 14:21:35,865 [Thread-4:-1243612352] [django.request:174] [WARNING]- Forbidden (CSRF cookie not set.): /topic/new/
2013-10-02 14:23:28,418 [Thread-5:-1243612352] [django.request:146] [WARNING]- Not Found: /admin
2013-10-02 14:29:15,055 [Thread-1:-1239418048] [django.request:212] [ERROR]- Internal Server Error: /admin
Traceback (most recent call last):
  File "/usr/local/lib/python2.7/dist-packages/django/core/handlers/base.py", line 92, in get_response
    response = middleware_method(request)
  File "/usr/local/lib/python2.7/dist-packages/django/middleware/common.py", line 69, in process_request
    if (not urlresolvers.is_valid_path(request.path_info, urlconf) and
  File "/usr/local/lib/python2.7/dist-packages/django/core/urlresolvers.py", line 551, in is_valid_path
    resolve(path, urlconf)
  File "/usr/local/lib/python2.7/dist-packages/django/core/urlresolvers.py", line 440, in resolve
    return get_resolver(urlconf).resolve(path)
  File "/usr/local/lib/python2.7/dist-packages/django/core/urlresolvers.py", line 319, in resolve
    for pattern in self.url_patterns:
  File "/usr/local/lib/python2.7/dist-packages/django/core/urlresolvers.py", line 347, in url_patterns
    patterns = getattr(self.urlconf_module, "urlpatterns", self.urlconf_module)
  File "/usr/local/lib/python2.7/dist-packages/django/core/urlresolvers.py", line 342, in urlconf_module
    self._urlconf_module = import_module(self.urlconf_name)
  File "/usr/local/lib/python2.7/dist-packages/django/utils/importlib.py", line 35, in import_module
    __import__(name)
  File "/home/cc/djcode/c28/c28/urls.py", line 12, in <module>
    url(r'^admin/', include(admin.site.urls)),
NameError: name 'admin' is not defined
2013-10-02 14:30:43,295 [Thread-3:-1239418048] [django.request:212] [ERROR]- Internal Server Error: /admin
Traceback (most recent call last):
  File "/usr/local/lib/python2.7/dist-packages/django/core/handlers/base.py", line 92, in get_response
    response = middleware_method(request)
  File "/usr/local/lib/python2.7/dist-packages/django/middleware/common.py", line 69, in process_request
    if (not urlresolvers.is_valid_path(request.path_info, urlconf) and
  File "/usr/local/lib/python2.7/dist-packages/django/core/urlresolvers.py", line 551, in is_valid_path
    resolve(path, urlconf)
  File "/usr/local/lib/python2.7/dist-packages/django/core/urlresolvers.py", line 440, in resolve
    return get_resolver(urlconf).resolve(path)
  File "/usr/local/lib/python2.7/dist-packages/django/core/urlresolvers.py", line 319, in resolve
    for pattern in self.url_patterns:
  File "/usr/local/lib/python2.7/dist-packages/django/core/urlresolvers.py", line 347, in url_patterns
    patterns = getattr(self.urlconf_module, "urlpatterns", self.urlconf_module)
  File "/usr/local/lib/python2.7/dist-packages/django/core/urlresolvers.py", line 342, in urlconf_module
    self._urlconf_module = import_module(self.urlconf_name)
  File "/usr/local/lib/python2.7/dist-packages/django/utils/importlib.py", line 35, in import_module
    __import__(name)
  File "/home/cc/djcode/c28/c28/urls.py", line 24, in <module>
    url(r'^admin/', include(admin.site.urls)),
NameError: name 'admin' is not defined
2013-10-02 14:31:11,119 [Thread-4:-1239418048] [django.request:212] [ERROR]- Internal Server Error: /admin
Traceback (most recent call last):
  File "/usr/local/lib/python2.7/dist-packages/django/core/handlers/base.py", line 92, in get_response
    response = middleware_method(request)
  File "/usr/local/lib/python2.7/dist-packages/django/middleware/common.py", line 69, in process_request
    if (not urlresolvers.is_valid_path(request.path_info, urlconf) and
  File "/usr/local/lib/python2.7/dist-packages/django/core/urlresolvers.py", line 551, in is_valid_path
    resolve(path, urlconf)
  File "/usr/local/lib/python2.7/dist-packages/django/core/urlresolvers.py", line 440, in resolve
    return get_resolver(urlconf).resolve(path)
  File "/usr/local/lib/python2.7/dist-packages/django/core/urlresolvers.py", line 319, in resolve
    for pattern in self.url_patterns:
  File "/usr/local/lib/python2.7/dist-packages/django/core/urlresolvers.py", line 347, in url_patterns
    patterns = getattr(self.urlconf_module, "urlpatterns", self.urlconf_module)
  File "/usr/local/lib/python2.7/dist-packages/django/core/urlresolvers.py", line 342, in urlconf_module
    self._urlconf_module = import_module(self.urlconf_name)
  File "/usr/local/lib/python2.7/dist-packages/django/utils/importlib.py", line 35, in import_module
    __import__(name)
  File "/home/cc/djcode/c28/c28/urls.py", line 7, in <module>
    admin.autodiscover()
  File "/usr/local/lib/python2.7/dist-packages/django/contrib/admin/__init__.py", line 29, in autodiscover
    import_module('%s.admin' % app)
  File "/usr/local/lib/python2.7/dist-packages/django/utils/importlib.py", line 35, in import_module
    __import__(name)
  File "/home/cc/djcode/c28/topics/admin.py", line 2, in <module>
    from c28.topics.models import Topic, Topic_reply
ImportError: No module named topics.models
2013-10-02 14:37:10,532 [Thread-1:-1240466624] [django.request:212] [ERROR]- Internal Server Error: /admin/
Traceback (most recent call last):
  File "/usr/local/lib/python2.7/dist-packages/django/core/handlers/base.py", line 103, in get_response
    resolver_match = resolver.resolve(request.path_info)
  File "/usr/local/lib/python2.7/dist-packages/django/core/urlresolvers.py", line 319, in resolve
    for pattern in self.url_patterns:
  File "/usr/local/lib/python2.7/dist-packages/django/core/urlresolvers.py", line 347, in url_patterns
    patterns = getattr(self.urlconf_module, "urlpatterns", self.urlconf_module)
  File "/usr/local/lib/python2.7/dist-packages/django/core/urlresolvers.py", line 342, in urlconf_module
    self._urlconf_module = import_module(self.urlconf_name)
  File "/usr/local/lib/python2.7/dist-packages/django/utils/importlib.py", line 35, in import_module
    __import__(name)
  File "/home/cc/djcode/c28/c28/urls.py", line 7, in <module>
    admin.autodiscover()
  File "/usr/local/lib/python2.7/dist-packages/django/contrib/admin/__init__.py", line 29, in autodiscover
    import_module('%s.admin' % app)
  File "/usr/local/lib/python2.7/dist-packages/django/utils/importlib.py", line 35, in import_module
    __import__(name)
  File "/home/cc/djcode/c28/account/admin.py", line 2, in <module>
    from admin.models import Account
ImportError: No module named models
2013-10-02 14:38:14,435 [Thread-20:-1274021056] [django.request:212] [ERROR]- Internal Server Error: /admin/account/account/add/
Traceback (most recent call last):
  File "/usr/local/lib/python2.7/dist-packages/django/core/handlers/base.py", line 115, in get_response
    response = callback(request, *callback_args, **callback_kwargs)
  File "/usr/local/lib/python2.7/dist-packages/django/contrib/admin/options.py", line 372, in wrapper
    return self.admin_site.admin_view(view)(*args, **kwargs)
  File "/usr/local/lib/python2.7/dist-packages/django/utils/decorators.py", line 91, in _wrapped_view
    response = view_func(request, *args, **kwargs)
  File "/usr/local/lib/python2.7/dist-packages/django/views/decorators/cache.py", line 89, in _wrapped_view_func
    response = view_func(request, *args, **kwargs)
  File "/usr/local/lib/python2.7/dist-packages/django/contrib/admin/sites.py", line 202, in inner
    return view(request, *args, **kwargs)
  File "/usr/local/lib/python2.7/dist-packages/django/utils/decorators.py", line 25, in _wrapper
    return bound_func(*args, **kwargs)
  File "/usr/local/lib/python2.7/dist-packages/django/utils/decorators.py", line 91, in _wrapped_view
    response = view_func(request, *args, **kwargs)
  File "/usr/local/lib/python2.7/dist-packages/django/utils/decorators.py", line 21, in bound_func
    return func(self, *args2, **kwargs2)
  File "/usr/local/lib/python2.7/dist-packages/django/db/transaction.py", line 223, in inner
    return func(*args, **kwargs)
  File "/usr/local/lib/python2.7/dist-packages/django/contrib/admin/options.py", line 1009, in add_view
    self.log_addition(request, new_object)
  File "/usr/local/lib/python2.7/dist-packages/django/contrib/admin/options.py", line 529, in log_addition
    object_repr     = force_text(object),
  File "/usr/local/lib/python2.7/dist-packages/django/utils/encoding.py", line 99, in force_text
    s = s.__unicode__()
  File "/home/cc/djcode/c28/account/models.py", line 11, in __unicode__
    return self.email
AttributeError: 'Account' object has no attribute 'email'
2013-10-02 14:40:30,934 [Thread-6:-1250952384] [django.request:212] [ERROR]- Internal Server Error: /admin/account/account/add/
Traceback (most recent call last):
  File "/usr/local/lib/python2.7/dist-packages/django/core/handlers/base.py", line 115, in get_response
    response = callback(request, *callback_args, **callback_kwargs)
  File "/usr/local/lib/python2.7/dist-packages/django/contrib/admin/options.py", line 372, in wrapper
    return self.admin_site.admin_view(view)(*args, **kwargs)
  File "/usr/local/lib/python2.7/dist-packages/django/utils/decorators.py", line 91, in _wrapped_view
    response = view_func(request, *args, **kwargs)
  File "/usr/local/lib/python2.7/dist-packages/django/views/decorators/cache.py", line 89, in _wrapped_view_func
    response = view_func(request, *args, **kwargs)
  File "/usr/local/lib/python2.7/dist-packages/django/contrib/admin/sites.py", line 202, in inner
    return view(request, *args, **kwargs)
  File "/usr/local/lib/python2.7/dist-packages/django/utils/decorators.py", line 25, in _wrapper
    return bound_func(*args, **kwargs)
  File "/usr/local/lib/python2.7/dist-packages/django/utils/decorators.py", line 91, in _wrapped_view
    response = view_func(request, *args, **kwargs)
  File "/usr/local/lib/python2.7/dist-packages/django/utils/decorators.py", line 21, in bound_func
    return func(self, *args2, **kwargs2)
  File "/usr/local/lib/python2.7/dist-packages/django/db/transaction.py", line 223, in inner
    return func(*args, **kwargs)
  File "/usr/local/lib/python2.7/dist-packages/django/contrib/admin/options.py", line 1009, in add_view
    self.log_addition(request, new_object)
  File "/usr/local/lib/python2.7/dist-packages/django/contrib/admin/options.py", line 530, in log_addition
    action_flag     = ADDITION
  File "/usr/local/lib/python2.7/dist-packages/django/contrib/admin/models.py", line 19, in log_action
    e.save()
  File "/usr/local/lib/python2.7/dist-packages/django/db/models/base.py", line 546, in save
    force_update=force_update, update_fields=update_fields)
  File "/usr/local/lib/python2.7/dist-packages/django/db/models/base.py", line 650, in save_base
    result = manager._insert([self], fields=fields, return_id=update_pk, using=using, raw=raw)
  File "/usr/local/lib/python2.7/dist-packages/django/db/models/manager.py", line 215, in _insert
    return insert_query(self.model, objs, fields, **kwargs)
  File "/usr/local/lib/python2.7/dist-packages/django/db/models/query.py", line 1675, in insert_query
    return query.get_compiler(using=using).execute_sql(return_id)
  File "/usr/local/lib/python2.7/dist-packages/django/db/models/sql/compiler.py", line 937, in execute_sql
    cursor.execute(sql, params)
  File "/usr/local/lib/python2.7/dist-packages/django/db/backends/util.py", line 41, in execute
    return self.cursor.execute(sql, params)
  File "/usr/local/lib/python2.7/dist-packages/django/db/backends/mysql/base.py", line 130, in execute
    six.reraise(utils.DatabaseError, utils.DatabaseError(*tuple(e.args)), sys.exc_info()[2])
  File "/usr/local/lib/python2.7/dist-packages/django/db/backends/mysql/base.py", line 120, in execute
    return self.cursor.execute(query, args)
  File "/usr/lib/python2.7/dist-packages/MySQLdb/cursors.py", line 174, in execute
    self.errorhandler(self, exc, value)
  File "/usr/lib/python2.7/dist-packages/MySQLdb/connections.py", line 36, in defaulterrorhandler
    raise errorclass, errorvalue
DatabaseError: (1146, "Table 'c28.django_admin_log' doesn't exist")
2013-10-02 14:42:17,376 [Thread-6:-1250952384] [django.request:212] [ERROR]- Internal Server Error: /admin/account/account/add/
Traceback (most recent call last):
  File "/usr/local/lib/python2.7/dist-packages/django/core/handlers/base.py", line 115, in get_response
    response = callback(request, *callback_args, **callback_kwargs)
  File "/usr/local/lib/python2.7/dist-packages/django/contrib/admin/options.py", line 372, in wrapper
    return self.admin_site.admin_view(view)(*args, **kwargs)
  File "/usr/local/lib/python2.7/dist-packages/django/utils/decorators.py", line 91, in _wrapped_view
    response = view_func(request, *args, **kwargs)
  File "/usr/local/lib/python2.7/dist-packages/django/views/decorators/cache.py", line 89, in _wrapped_view_func
    response = view_func(request, *args, **kwargs)
  File "/usr/local/lib/python2.7/dist-packages/django/contrib/admin/sites.py", line 202, in inner
    return view(request, *args, **kwargs)
  File "/usr/local/lib/python2.7/dist-packages/django/utils/decorators.py", line 25, in _wrapper
    return bound_func(*args, **kwargs)
  File "/usr/local/lib/python2.7/dist-packages/django/utils/decorators.py", line 91, in _wrapped_view
    response = view_func(request, *args, **kwargs)
  File "/usr/local/lib/python2.7/dist-packages/django/utils/decorators.py", line 21, in bound_func
    return func(self, *args2, **kwargs2)
  File "/usr/local/lib/python2.7/dist-packages/django/db/transaction.py", line 223, in inner
    return func(*args, **kwargs)
  File "/usr/local/lib/python2.7/dist-packages/django/contrib/admin/options.py", line 1007, in add_view
    self.save_model(request, new_object, form, False)
  File "/usr/local/lib/python2.7/dist-packages/django/contrib/admin/options.py", line 740, in save_model
    obj.save()
  File "/usr/local/lib/python2.7/dist-packages/django/db/models/base.py", line 546, in save
    force_update=force_update, update_fields=update_fields)
  File "/usr/local/lib/python2.7/dist-packages/django/db/models/base.py", line 650, in save_base
    result = manager._insert([self], fields=fields, return_id=update_pk, using=using, raw=raw)
  File "/usr/local/lib/python2.7/dist-packages/django/db/models/manager.py", line 215, in _insert
    return insert_query(self.model, objs, fields, **kwargs)
  File "/usr/local/lib/python2.7/dist-packages/django/db/models/query.py", line 1675, in insert_query
    return query.get_compiler(using=using).execute_sql(return_id)
  File "/usr/local/lib/python2.7/dist-packages/django/db/models/sql/compiler.py", line 937, in execute_sql
    cursor.execute(sql, params)
  File "/usr/local/lib/python2.7/dist-packages/django/db/backends/util.py", line 41, in execute
    return self.cursor.execute(sql, params)
  File "/usr/local/lib/python2.7/dist-packages/django/db/backends/mysql/base.py", line 127, in execute
    six.reraise(utils.IntegrityError, utils.IntegrityError(*tuple(e.args)), sys.exc_info()[2])
  File "/usr/local/lib/python2.7/dist-packages/django/db/backends/mysql/base.py", line 120, in execute
    return self.cursor.execute(query, args)
  File "/usr/lib/python2.7/dist-packages/MySQLdb/cursors.py", line 174, in execute
    self.errorhandler(self, exc, value)
  File "/usr/lib/python2.7/dist-packages/MySQLdb/connections.py", line 36, in defaulterrorhandler
    raise errorclass, errorvalue
IntegrityError: (1048, "Column 'birthday' cannot be null")
2013-10-02 14:47:56,936 [Thread-11:-1239418048] [django.request:212] [ERROR]- Internal Server Error: /admin/topics/topic_reply/
Traceback (most recent call last):
  File "/usr/local/lib/python2.7/dist-packages/django/core/handlers/base.py", line 140, in get_response
    response = response.render()
  File "/usr/local/lib/python2.7/dist-packages/django/template/response.py", line 105, in render
    self.content = self.rendered_content
  File "/usr/local/lib/python2.7/dist-packages/django/template/response.py", line 82, in rendered_content
    content = template.render(context)
  File "/usr/local/lib/python2.7/dist-packages/django/template/base.py", line 140, in render
    return self._render(context)
  File "/usr/local/lib/python2.7/dist-packages/django/template/base.py", line 134, in _render
    return self.nodelist.render(context)
  File "/usr/local/lib/python2.7/dist-packages/django/template/base.py", line 830, in render
    bit = self.render_node(node, context)
  File "/usr/local/lib/python2.7/dist-packages/django/template/debug.py", line 74, in render_node
    return node.render(context)
  File "/usr/local/lib/python2.7/dist-packages/django/template/loader_tags.py", line 124, in render
    return compiled_parent._render(context)
  File "/usr/local/lib/python2.7/dist-packages/django/template/base.py", line 134, in _render
    return self.nodelist.render(context)
  File "/usr/local/lib/python2.7/dist-packages/django/template/base.py", line 830, in render
    bit = self.render_node(node, context)
  File "/usr/local/lib/python2.7/dist-packages/django/template/debug.py", line 74, in render_node
    return node.render(context)
  File "/usr/local/lib/python2.7/dist-packages/django/template/loader_tags.py", line 124, in render
    return compiled_parent._render(context)
  File "/usr/local/lib/python2.7/dist-packages/django/template/base.py", line 134, in _render
    return self.nodelist.render(context)
  File "/usr/local/lib/python2.7/dist-packages/django/template/base.py", line 830, in render
    bit = self.render_node(node, context)
  File "/usr/local/lib/python2.7/dist-packages/django/template/debug.py", line 74, in render_node
    return node.render(context)
  File "/usr/local/lib/python2.7/dist-packages/django/template/loader_tags.py", line 63, in render
    result = block.nodelist.render(context)
  File "/usr/local/lib/python2.7/dist-packages/django/template/base.py", line 830, in render
    bit = self.render_node(node, context)
  File "/usr/local/lib/python2.7/dist-packages/django/template/debug.py", line 74, in render_node
    return node.render(context)
  File "/usr/local/lib/python2.7/dist-packages/django/template/loader_tags.py", line 63, in render
    result = block.nodelist.render(context)
  File "/usr/local/lib/python2.7/dist-packages/django/template/base.py", line 830, in render
    bit = self.render_node(node, context)
  File "/usr/local/lib/python2.7/dist-packages/django/template/debug.py", line 74, in render_node
    return node.render(context)
  File "/usr/local/lib/python2.7/dist-packages/django/template/base.py", line 1185, in render
    _dict = func(*resolved_args, **resolved_kwargs)
  File "/usr/local/lib/python2.7/dist-packages/django/contrib/admin/templatetags/admin_list.py", line 286, in result_list
    'results': list(results(cl))}
  File "/usr/local/lib/python2.7/dist-packages/django/contrib/admin/templatetags/admin_list.py", line 264, in results
    yield ResultList(None, items_for_result(cl, res, None))
  File "/usr/local/lib/python2.7/dist-packages/django/contrib/admin/templatetags/admin_list.py", line 256, in __init__
    super(ResultList, self).__init__(*items)
  File "/usr/local/lib/python2.7/dist-packages/django/contrib/admin/templatetags/admin_list.py", line 184, in items_for_result
    f, attr, value = lookup_field(field_name, result, cl.model_admin)
  File "/usr/local/lib/python2.7/dist-packages/django/contrib/admin/util.py", line 258, in lookup_field
    value = attr()
  File "/usr/local/lib/python2.7/dist-packages/django/db/models/base.py", line 433, in __str__
    return force_text(self).encode('utf-8')
AttributeError: 'tuple' object has no attribute 'encode'
2013-10-02 14:48:29,434 [Thread-1:-1240466624] [django.request:212] [ERROR]- Internal Server Error: /admin/topics/topic_reply/
Traceback (most recent call last):
  File "/usr/local/lib/python2.7/dist-packages/django/core/handlers/base.py", line 140, in get_response
    response = response.render()
  File "/usr/local/lib/python2.7/dist-packages/django/template/response.py", line 105, in render
    self.content = self.rendered_content
  File "/usr/local/lib/python2.7/dist-packages/django/template/response.py", line 82, in rendered_content
    content = template.render(context)
  File "/usr/local/lib/python2.7/dist-packages/django/template/base.py", line 140, in render
    return self._render(context)
  File "/usr/local/lib/python2.7/dist-packages/django/template/base.py", line 134, in _render
    return self.nodelist.render(context)
  File "/usr/local/lib/python2.7/dist-packages/django/template/base.py", line 830, in render
    bit = self.render_node(node, context)
  File "/usr/local/lib/python2.7/dist-packages/django/template/debug.py", line 74, in render_node
    return node.render(context)
  File "/usr/local/lib/python2.7/dist-packages/django/template/loader_tags.py", line 124, in render
    return compiled_parent._render(context)
  File "/usr/local/lib/python2.7/dist-packages/django/template/base.py", line 134, in _render
    return self.nodelist.render(context)
  File "/usr/local/lib/python2.7/dist-packages/django/template/base.py", line 830, in render
    bit = self.render_node(node, context)
  File "/usr/local/lib/python2.7/dist-packages/django/template/debug.py", line 74, in render_node
    return node.render(context)
  File "/usr/local/lib/python2.7/dist-packages/django/template/loader_tags.py", line 124, in render
    return compiled_parent._render(context)
  File "/usr/local/lib/python2.7/dist-packages/django/template/base.py", line 134, in _render
    return self.nodelist.render(context)
  File "/usr/local/lib/python2.7/dist-packages/django/template/base.py", line 830, in render
    bit = self.render_node(node, context)
  File "/usr/local/lib/python2.7/dist-packages/django/template/debug.py", line 74, in render_node
    return node.render(context)
  File "/usr/local/lib/python2.7/dist-packages/django/template/loader_tags.py", line 63, in render
    result = block.nodelist.render(context)
  File "/usr/local/lib/python2.7/dist-packages/django/template/base.py", line 830, in render
    bit = self.render_node(node, context)
  File "/usr/local/lib/python2.7/dist-packages/django/template/debug.py", line 74, in render_node
    return node.render(context)
  File "/usr/local/lib/python2.7/dist-packages/django/template/loader_tags.py", line 63, in render
    result = block.nodelist.render(context)
  File "/usr/local/lib/python2.7/dist-packages/django/template/base.py", line 830, in render
    bit = self.render_node(node, context)
  File "/usr/local/lib/python2.7/dist-packages/django/template/debug.py", line 74, in render_node
    return node.render(context)
  File "/usr/local/lib/python2.7/dist-packages/django/template/base.py", line 1185, in render
    _dict = func(*resolved_args, **resolved_kwargs)
  File "/usr/local/lib/python2.7/dist-packages/django/contrib/admin/templatetags/admin_list.py", line 286, in result_list
    'results': list(results(cl))}
  File "/usr/local/lib/python2.7/dist-packages/django/contrib/admin/templatetags/admin_list.py", line 264, in results
    yield ResultList(None, items_for_result(cl, res, None))
  File "/usr/local/lib/python2.7/dist-packages/django/contrib/admin/templatetags/admin_list.py", line 256, in __init__
    super(ResultList, self).__init__(*items)
  File "/usr/local/lib/python2.7/dist-packages/django/contrib/admin/templatetags/admin_list.py", line 184, in items_for_result
    f, attr, value = lookup_field(field_name, result, cl.model_admin)
  File "/usr/local/lib/python2.7/dist-packages/django/contrib/admin/util.py", line 258, in lookup_field
    value = attr()
  File "/usr/local/lib/python2.7/dist-packages/django/db/models/base.py", line 433, in __str__
    return force_text(self).encode('utf-8')
AttributeError: 'long' object has no attribute 'encode'
